Workbook

Sheet Hito 1
A1: Hito 1 · Cimientos
A2: Fases 0 y 1 del plan. Ninguna de estas tareas añade funcionalidad: existen para que los hitos 2 a 4 se puedan hacer deprisa y sin miedo. Al terminar, el motor hace exactamente lo de hoy pero ya hablando de casos, y cualquier rotura salta sola.
A3: Edita solo la columna Estado (lista desplegable). El color de la fila y la pestaña «Todas las tareas» se actualizan solos.
A5: ID | B5: Nombre | C5: Descripción | D5: Estado
A6: 1.1 | B6: Semilla configurable y registrada | C6: Parámetro de simulación opcional; si viene vacío, el motor genera una. Se adelanta desde el hito 4 porque sin determinismo el banco de pruebas no sirve. Ficheros: main.py, generateScript.py, runtime.py. Terminada cuando dos ejecuciones con la misma semilla dan XES idénticos y el log dice cuál se usó. | D6: To Do
A7: 1.2 | B7: Modelos de referencia congelados | C7: Uno simple, una colaboración 1:1, y uno con uniones paralelas e inclusivas y un bucle. Ficheros: carpeta nueva Backend/pruebas/modelos/. Terminada cuando los tres están versionados y el motor los ejecuta sin error ni aviso inesperado. | D7: To Do
A8: 1.3 | B8: Script de regresión | C8: Reejecuta los modelos de referencia y compara contra el XES guardado. Ficheros: Backend/pruebas/regresion.py. Terminada cuando cambiar un número a mano lo hace fallar diciendo qué traza y qué evento no cuadran. | D8: To Do
A9: 1.4 | B9: El caso en el runtime | C9: simulationResults, active_tokens, pending_joins, data, data_changed y completed pasan a indexarse por el par (participante, índice). Ficheros: runtime.py. Terminada cuando la regresión sigue en verde. | D9: To Do
A10: 1.5 | B10: El caso en las funciones generadas | C10: Sustituir name y eliminar name.split()[-1], que es de donde sale hoy el número de instancia. Ficheros: simulationFunctions/*.py, generateScript.py. Terminada cuando bpmn:instance viene de un campo del caso y la regresión sigue en verde. | D10: To Do
A11: 1.6 | B11: El caso en el XES | C11: Nombre de traza, metadatos y clasificador. Ficheros: runtime.py, generateScript.py. Terminada cuando PM4Py lee el log y el nombre de la traza identifica pool e índice. | D11: To Do

Sheet Hito 2
A1: Hito 2 · Dos procesos a la vez
A2: Fases 2 y 3 del plan. Aquí aparece el 1:N de verdad, pero todavía sin semántica de lote: los mensajes van y vienen de uno en uno. Al terminar, un orquestador de 1 instancia y un orquestado de 50 corren juntos, con recursos separados, y se hablan.
A3: Edita solo la columna Estado (lista desplegable). El color de la fila y la pestaña «Todas las tareas» se actualizan solos.
A5: ID | B5: Nombre | C5: Descripción | D5: Estado
A6: 2.1 | B6: Multiplicidad del pool en las reglas | C6: Campo instances en el participante, y la regla de compatibilidad: sin ningún marcador manda el de la colaboración, con marcador cada pool el suyo y el que no lo lleva vale 1. Ficheros: models/baseModels.py, parser.py, validation.py. Terminada cuando dos pools de 1 y 50 dan 51 casos y los modelos de referencia siguen dando lo de antes. | D6: To Do
A7: 2.2 | B7: Tabla de casos y arranque por participante | C7: Construirla entera antes de env.run() y lanzar los eventos de inicio de cada pool con su propia frecuencia. Ficheros: runtime.py, generateScript.py. Terminada cuando cada pool arranca a su ritmo y el XES lo refleja. | D7: To Do
A8: 2.3 | B8: Colas de usuarios por pool y recursos infinitos | C8: Una UserQueue por participante en vez de una global, más la casilla de recursos infinitos del pool. Ficheros: runtime.py, generateScript.py, parser.py, validation.py. Terminada cuando dos pools que declaran el mismo nombre de usuario no se roban el recurso, y el pool marcado como infinito no registra ni una espera. | D8: To Do
A9: 2.4 | B9: Clave de mensaje por caso destino | C9: La clave pasa a llevar el caso destino y el envío arrastra el caso remitente. Ficheros: runtime.py, sendTask.py, receiveTask.py, events.py. Terminada cuando un 1:1 entre dos pools de una instancia sigue funcionando y un mensaje sin destino posible da un error que nombra origen y destino. | D9: To Do
A10: 2.5 | B10: Contenido del mensaje | C10: Estructura de campos con nombre, que hoy solo lleva el resultado y mañana puede llevar más sin tocar el emparejamiento. Ficheros: runtime.py, sendTask.py, receiveTask.py, events.py. Terminada cuando el receptor lee el campo y el valor aparece en su evento del XES. | D10: To Do
A11: 2.6 | B11: Encaminamiento 1→N y N→1 | C11: Una copia por caso vivo del pool destino, y un único destino cuando el pool de enfrente tiene una instancia. Ficheros: runtime.py. Terminada cuando un envío a un pool de 50 publica 50 copias, incluidas las de los casos que aún no han arrancado, y las 50 respuestas llegan al caso único. | D11: To Do

Sheet Hito 3
A1: Hito 3 · El lote
A2: Fases 4 y 5 del plan. El hito que justifica el proyecto, y el único donde casi todo es código nuevo en vez de refactor. El orden interno importa: el colector antes que el sorteo, y la asociación dibujada antes que el gateway que la usa. Al terminar, la convocatoria funciona de punta a punta.
A3: Edita solo la columna Estado (lista desplegable). El color de la fila y la pestaña «Todas las tareas» se actualizan solos.
A5: ID | B5: Nombre | C5: Descripción | D5: Estado
A6: 3.1 | B6: Tarea «enviar a N» | C6: Publica una copia por instancia del pool de enfrente, con el remitente dentro. Ficheros: models/taskModels.py, parser.py, simulationFunctions/generateFunction.py y un módulo nuevo. Terminada cuando un envío a 50 deja 50 mensajes y lo registra una vez por destino. | D6: To Do
A7: 3.2 | B7: Tarea «recoger de N» | C7: Apertura, acumulación y cierre por plazo, por cupo o al entrar las N, lo que ocurra primero. Ficheros: módulo nuevo, models/taskModels.py, parser.py, runtime.py. Terminada cuando los tres cierres funcionan sueltos y combinados, y el XES registra apertura y cierre con su motivo. | D7: To Do
A8: 3.3 | B8: La espera del emisor | C8: Quien envía a un colector no suelta el mensaje hasta que el colector abre. Ficheros: runtime.py y los dos módulos de envío. Terminada cuando un orquestado que arranca en el segundo 0 con el colector abriendo en el 200 registra su espera y entra dentro de plazo. | D8: To Do
A9: 3.4 | B9: Rechazo de lo que llega fuera | C9: Tarde o pasado el cupo, el colector responde con rechazo en vez de dejar el mensaje colgado. Ficheros: runtime.py y el módulo del colector. Terminada cuando una solicitud posterior al cierre recibe respuesta y la simulación no se bloquea. | D9: To Do
A10: 3.5 | B10: Tarea «evaluar N» | C10: Cardinalidad igual a lo recogido, un recurso por solicitud, en paralelo con tope opcional de ejecuciones simultáneas. Ficheros: módulo nuevo, models/taskModels.py, parser.py, runtime.py. Terminada cuando con 100 solicitudes y tope 5 nunca hay más de 5 evaluaciones simultáneas, y sin tope hay 100. | D10: To Do
A11: 3.6 | B11: La asociación dibujada en el motor | C11: Dejar de descartar Association y resolver a qué tarea apunta cada gateway y cada evaluadora. Ficheros: parser.py, validation.py. Terminada cuando la asociación llega al motor y una que apunte a un elemento que no toca da error. | D11: To Do
A12: 3.7 | B12: El sorteo de plazas | C12: Al terminar la evaluación, reparte las plazas entre lo recogido y marca el resto como rechazado. Ficheros: módulo de la evaluadora, runtime.py. Terminada cuando de 100 recogidas con 50 plazas salen exactamente 50 aceptadas, idénticas con la misma semilla. | D12: To Do
A13: 3.8 | B13: El gateway nuevo | C13: Lee el resultado que vino en el mensaje y encamina por el flujo que lo declara. Ficheros: simulationFunctions/gateways.py, models/gatewayModels.py, parser.py. Terminada cuando el número de aceptados del log del orquestador cuadra exactamente con el de orquestados que toman la rama de aceptado. | D13: To Do
A14: 3.9 | B14: El rechazo que termina el proceso | C14: Casilla en el pool y evento final sintético. Ficheros: runtime.py, parser.py, validation.py. Terminada cuando con la casilla puesta el rechazado cierra su traza con un evento reconocible, y sin ella toma la rama de reclamación. | D14: To Do
A15: 3.10 | B15: Validación y diagnóstico del lote | C15: Colector sin plazo ni cupo cuando el número de emisores no se conoce, gateway sin asociación, flujo sin resultado, mensajes entre dos pools múltiples, y un bloqueo que diga quién esperaba qué y desde cuándo. Ficheros: validation.py, runtime.py. Terminada cuando cada modelo mal formado da su propio error y un bloqueo real nombra elemento, caso e instante. | D15: To Do

Sheet Hito 4
A1: Hito 4 · El experimento
A2: Fases 6 y 7 del plan. Convierte el motor en algo con lo que se puede experimentar de verdad: varias rondas, llegadas configurables, un registro por pool y un número que diga lo que cuesta.
A3: Edita solo la columna Estado (lista desplegable). El color de la fila y la pestaña «Todas las tareas» se actualizan solos.
A5: ID | B5: Nombre | C5: Descripción | D5: Estado
A6: 4.1 | B6: Fin de instancia y convocatorias en serie | C6: El motor necesita saber cuándo un caso ha terminado del todo para arrancar el siguiente; hoy solo cuenta eventos de fin. Ficheros: runtime.py, generateScript.py. Terminada cuando tres convocatorias seguidas no solapan un solo evento. | D6: To Do
A7: 4.2 | B7: Orquestados nuevos por ronda | C7: Los casos del pool orquestado se crean al empezar cada convocatoria. Ficheros: runtime.py. Terminada cuando el XES del orquestado tiene N trazas por ronda y ninguna cruza de una a otra. | D7: To Do
A8: 4.3 | B8: Los tres modos de llegada | C8: Escalonada cada frequency, todas en el instante 0, o al azar entre 0 y T. Ficheros: models/baseModels.py, parser.py, runtime.py. Terminada cuando los tres dan histogramas de llegada distintos y el modo al azar nunca se pasa de T. | D8: To Do
A9: 4.4 | B9: Un XES por participante | C9: Un fichero por pool, con sus propios metadatos y sus trazas. Ficheros: runtime.py, generateScript.py. Terminada cuando PM4Py descubre el modelo de cada pool a partir de su fichero. | D9: To Do
A10: 4.5 | B10: La respuesta del servidor | C10: Varios registros en vez de una cadena. Ficheros: main.py, server.py. Terminada cuando el servidor devuelve un registro por pool, cada uno validado como XES, y los avisos siguen llegando igual. | D10: To Do
A11: 4.6 | B11: El proceso base y su coste | C11: La convocatoria escrita como reglas, metida en la regresión, y medida con N de 10, 50 y 100. Ficheros: Backend/pruebas/modelos/. Terminada cuando el modelo corre de punta a punta y hay un número de segundos para cada N. | D11: To Do

Sheet Hito 5
A1: Hito 5 · El Modeler
A2: Fase 8 del plan. Se puede empezar en cuanto el formato de las reglas quede fijado, al final del hito 3, y es la parte más fácil de repartir si en algún momento hay más manos. Hasta que esté hecho, el motor se prueba con reglas escritas a mano.
A3: Edita solo la columna Estado (lista desplegable). El color de la fila y la pestaña «Todas las tareas» se actualizan solos.
A5: ID | B5: Nombre | C5: Descripción | D5: Estado
A6: 5.1 | B6: Descriptor del participante | C6: instances, recursos infinitos, modo de llegada con su T, y la casilla de rechazo que termina el proceso. Ficheros: descriptors/participantWithoutLane.json. Terminada cuando los atributos se guardan en el .bpmn y se releen al abrirlo. | D6: To Do
A7: 5.2 | B7: Descriptores de los elementos nuevos | C7: Las tres tareas, el gateway, y la semilla en la colaboración. Ficheros: dos descriptores nuevos más collaboration.json. Terminada cuando los elementos conservan sus parámetros al guardar y volver a abrir. | D7: To Do
A8: 5.3 | B8: Paneles de propiedades | C8: Ficheros: provider/model/parts/, provider/properties/PropertiesProvider.js. Terminada cuando cada campo aparece solo donde tiene sentido: el número de instancias con el marcador puesto, el plazo y el cupo solo en el colector, el tope solo en la evaluadora. | D8: To Do
A9: 5.4 | B9: Iconos y renderizado | C9: Los tres tipos de tarea y el gateway nuevo. Ficheros: módulo nuevo en Modeler/lib/. Terminada cuando los cuatro se distinguen a simple vista en el lienzo y al imprimir en blanco y negro. | D9: To Do
A10: 5.5 | B10: Paleta y menú de reemplazo | C10: Ficheros: módulo nuevo. Terminada cuando se crean desde la paleta y una tarea normal se convierte en cualquiera de los tres tipos sin perder sus datos. | D10: To Do
A11: 5.6 | B11: Reglas de modelado de la asociación | C11: Ficheros: Modeler/lib/. Terminada cuando se puede trazar la asociación de gateway a tarea y de evaluadora a colector, y el editor la rechaza hacia cualquier otra cosa. | D11: To Do
A12: 5.7 | B12: Exportación de las reglas | C12: Todo lo anterior, incluidas las asociaciones, que hoy no se exportan. Ficheros: example/src/taskHandlers.js. Terminada cuando las reglas que saca el Modeler dan exactamente la misma simulación que las escritas a mano. | D12: To Do
A13: 5.8 | B13: Descarga de varios registros | C13: Ficheros: example/src/modeler.js, modeler.html, style.css. Terminada cuando la interfaz ofrece un XES por pool, cada uno con el nombre de su pool. | D13: To Do
A14: 5.9 | B14: El proceso base dibujado y documentado | C14: Ficheros: Backend/README.md, Modeler/README.md. Terminada cuando la convocatoria se dibuja y se simula desde el Modeler sin tocar un fichero de reglas, y el .bpmn abre en otra herramienta sin romperse. | D14: To Do

Sheet Todas las tareas
A1: Todas las tareas
A2: Las 37 tareas en el orden recomendado de ejecución. Dentro de cada hito el orden importa; entre hitos, el único que se puede adelantar es el 5, que puede empezar en cuanto termine la tarea 3.10. El estado se toma de la pestaña de cada hito.
A3: Solo lectura: cambia el estado en la pestaña de su hito y esta tabla y el gráfico se actualizan solos.
A5: ID | B5: Nombre | C5: Descripción | D5: Estado | F5: Estado | G5: Tareas
A6: 1.1 | B6: Semilla configurable y registrada | C6: Parámetro de simulación opcional; si viene vacío, el motor genera una. Se adelanta desde el hito 4 porque sin determinismo el banco de pruebas no sirve. Ficheros: main.py, generateScript.py, runtime.py. Terminada cuando dos ejecuciones con la misma semilla dan XES idénticos y el log dice cuál se usó. | D6: ='Hito 1'!D6 -> To Do | F6: To Do | G6: =COUNTIF($D$6:$D$42,$F6) -> 37
A7: 1.2 | B7: Modelos de referencia congelados | C7: Uno simple, una colaboración 1:1, y uno con uniones paralelas e inclusivas y un bucle. Ficheros: carpeta nueva Backend/pruebas/modelos/. Terminada cuando los tres están versionados y el motor los ejecuta sin error ni aviso inesperado. | D7: ='Hito 1'!D7 -> To Do | F7: In Progress | G7: =COUNTIF($D$6:$D$42,$F7) -> 0
A8: 1.3 | B8: Script de regresión | C8: Reejecuta los modelos de referencia y compara contra el XES guardado. Ficheros: Backend/pruebas/regresion.py. Terminada cuando cambiar un número a mano lo hace fallar diciendo qué traza y qué evento no cuadran. | D8: ='Hito 1'!D8 -> To Do | F8: In Review | G8: =COUNTIF($D$6:$D$42,$F8) -> 0
A9: 1.4 | B9: El caso en el runtime | C9: simulationResults, active_tokens, pending_joins, data, data_changed y completed pasan a indexarse por el par (participante, índice). Ficheros: runtime.py. Terminada cuando la regresión sigue en verde. | D9: ='Hito 1'!D9 -> To Do | F9: DONE | G9: =COUNTIF($D$6:$D$42,$F9) -> 0
A10: 1.5 | B10: El caso en las funciones generadas | C10: Sustituir name y eliminar name.split()[-1], que es de donde sale hoy el número de instancia. Ficheros: simulationFunctions/*.py, generateScript.py. Terminada cuando bpmn:instance viene de un campo del caso y la regresión sigue en verde. | D10: ='Hito 1'!D10 -> To Do | F10: Total | G10: =SUM($G$6:$G$9) -> 37
A11: 1.6 | B11: El caso en el XES | C11: Nombre de traza, metadatos y clasificador. Ficheros: runtime.py, generateScript.py. Terminada cuando PM4Py lee el log y el nombre de la traza identifica pool e índice. | D11: ='Hito 1'!D11 -> To Do
A12: 2.1 | B12: Multiplicidad del pool en las reglas | C12: Campo instances en el participante, y la regla de compatibilidad: sin ningún marcador manda el de la colaboración, con marcador cada pool el suyo y el que no lo lleva vale 1. Ficheros: models/baseModels.py, parser.py, validation.py. Terminada cuando dos pools de 1 y 50 dan 51 casos y los modelos de referencia siguen dando lo de antes. | D12: ='Hito 2'!D6 -> To Do | F12: Completado | G12: =IFERROR($G$9/$G$10,0) -> 0
A13: 2.2 | B13: Tabla de casos y arranque por participante | C13: Construirla entera antes de env.run() y lanzar los eventos de inicio de cada pool con su propia frecuencia. Ficheros: runtime.py, generateScript.py. Terminada cuando cada pool arranca a su ritmo y el XES lo refleja. | D13: ='Hito 2'!D7 -> To Do
A14: 2.3 | B14: Colas de usuarios por pool y recursos infinitos | C14: Una UserQueue por participante en vez de una global, más la casilla de recursos infinitos del pool. Ficheros: runtime.py, generateScript.py, parser.py, validation.py. Terminada cuando dos pools que declaran el mismo nombre de usuario no se roban el recurso, y el pool marcado como infinito no registra ni una espera. | D14: ='Hito 2'!D8 -> To Do
A15: 2.4 | B15: Clave de mensaje por caso destino | C15: La clave pasa a llevar el caso destino y el envío arrastra el caso remitente. Ficheros: runtime.py, sendTask.py, receiveTask.py, events.py. Terminada cuando un 1:1 entre dos pools de una instancia sigue funcionando y un mensaje sin destino posible da un error que nombra origen y destino. | D15: ='Hito 2'!D9 -> To Do
A16: 2.5 | B16: Contenido del mensaje | C16: Estructura de campos con nombre, que hoy solo lleva el resultado y mañana puede llevar más sin tocar el emparejamiento. Ficheros: runtime.py, sendTask.py, receiveTask.py, events.py. Terminada cuando el receptor lee el campo y el valor aparece en su evento del XES. | D16: ='Hito 2'!D10 -> To Do
A17: 2.6 | B17: Encaminamiento 1→N y N→1 | C17: Una copia por caso vivo del pool destino, y un único destino cuando el pool de enfrente tiene una instancia. Ficheros: runtime.py. Terminada cuando un envío a un pool de 50 publica 50 copias, incluidas las de los casos que aún no han arrancado, y las 50 respuestas llegan al caso único. | D17: ='Hito 2'!D11 -> To Do
A18: 3.1 | B18: Tarea «enviar a N» | C18: Publica una copia por instancia del pool de enfrente, con el remitente dentro. Ficheros: models/taskModels.py, parser.py, simulationFunctions/generateFunction.py y un módulo nuevo. Terminada cuando un envío a 50 deja 50 mensajes y lo registra una vez por destino. | D18: ='Hito 3'!D6 -> To Do
A19: 3.2 | B19: Tarea «recoger de N» | C19: Apertura, acumulación y cierre por plazo, por cupo o al entrar las N, lo que ocurra primero. Ficheros: módulo nuevo, models/taskModels.py, parser.py, runtime.py. Terminada cuando los tres cierres funcionan sueltos y combinados, y el XES registra apertura y cierre con su motivo. | D19: ='Hito 3'!D7 -> To Do
A20: 3.3 | B20: La espera del emisor | C20: Quien envía a un colector no suelta el mensaje hasta que el colector abre. Ficheros: runtime.py y los dos módulos de envío. Terminada cuando un orquestado que arranca en el segundo 0 con el colector abriendo en el 200 registra su espera y entra dentro de plazo. | D20: ='Hito 3'!D8 -> To Do
A21: 3.4 | B21: Rechazo de lo que llega fuera | C21: Tarde o pasado el cupo, el colector responde con rechazo en vez de dejar el mensaje colgado. Ficheros: runtime.py y el módulo del colector. Terminada cuando una solicitud posterior al cierre recibe respuesta y la simulación no se bloquea. | D21: ='Hito 3'!D9 -> To Do
A22: 3.5 | B22: Tarea «evaluar N» | C22: Cardinalidad igual a lo recogido, un recurso por solicitud, en paralelo con tope opcional de ejecuciones simultáneas. Ficheros: módulo nuevo, models/taskModels.py, parser.py, runtime.py. Terminada cuando con 100 solicitudes y tope 5 nunca hay más de 5 evaluaciones simultáneas, y sin tope hay 100. | D22: ='Hito 3'!D10 -> To Do
A23: 3.6 | B23: La asociación dibujada en el motor | C23: Dejar de descartar Association y resolver a qué tarea apunta cada gateway y cada evaluadora. Ficheros: parser.py, validation.py. Terminada cuando la asociación llega al motor y una que apunte a un elemento que no toca da error. | D23: ='Hito 3'!D11 -> To Do
A24: 3.7 | B24: El sorteo de plazas | C24: Al terminar la evaluación, reparte las plazas entre lo recogido y marca el resto como rechazado. Ficheros: módulo de la evaluadora, runtime.py. Terminada cuando de 100 recogidas con 50 plazas salen exactamente 50 aceptadas, idénticas con la misma semilla. | D24: ='Hito 3'!D12 -> To Do
A25: 3.8 | B25: El gateway nuevo | C25: Lee el resultado que vino en el mensaje y encamina por el flujo que lo declara. Ficheros: simulationFunctions/gateways.py, models/gatewayModels.py, parser.py. Terminada cuando el número de aceptados del log del orquestador cuadra exactamente con el de orquestados que toman la rama de aceptado. | D25: ='Hito 3'!D13 -> To Do
A26: 3.9 | B26: El rechazo que termina el proceso | C26: Casilla en el pool y evento final sintético. Ficheros: runtime.py, parser.py, validation.py. Terminada cuando con la casilla puesta el rechazado cierra su traza con un evento reconocible, y sin ella toma la rama de reclamación. | D26: ='Hito 3'!D14 -> To Do
A27: 3.10 | B27: Validación y diagnóstico del lote | C27: Colector sin plazo ni cupo cuando el número de emisores no se conoce, gateway sin asociación, flujo sin resultado, mensajes entre dos pools múltiples, y un bloqueo que diga quién esperaba qué y desde cuándo. Ficheros: validation.py, runtime.py. Terminada cuando cada modelo mal formado da su propio error y un bloqueo real nombra elemento, caso e instante. | D27: ='Hito 3'!D15 -> To Do
A28: 4.1 | B28: Fin de instancia y convocatorias en serie | C28: El motor necesita saber cuándo un caso ha terminado del todo para arrancar el siguiente; hoy solo cuenta eventos de fin. Ficheros: runtime.py, generateScript.py. Terminada cuando tres convocatorias seguidas no solapan un solo evento. | D28: ='Hito 4'!D6 -> To Do
A29: 4.2 | B29: Orquestados nuevos por ronda | C29: Los casos del pool orquestado se crean al empezar cada convocatoria. Ficheros: runtime.py. Terminada cuando el XES del orquestado tiene N trazas por ronda y ninguna cruza de una a otra. | D29: ='Hito 4'!D7 -> To Do
A30: 4.3 | B30: Los tres modos de llegada | C30: Escalonada cada frequency, todas en el instante 0, o al azar entre 0 y T. Ficheros: models/baseModels.py, parser.py, runtime.py. Terminada cuando los tres dan histogramas de llegada distintos y el modo al azar nunca se pasa de T. | D30: ='Hito 4'!D8 -> To Do
A31: 4.4 | B31: Un XES por participante | C31: Un fichero por pool, con sus propios metadatos y sus trazas. Ficheros: runtime.py, generateScript.py. Terminada cuando PM4Py descubre el modelo de cada pool a partir de su fichero. | D31: ='Hito 4'!D9 -> To Do
A32: 4.5 | B32: La respuesta del servidor | C32: Varios registros en vez de una cadena. Ficheros: main.py, server.py. Terminada cuando el servidor devuelve un registro por pool, cada uno validado como XES, y los avisos siguen llegando igual. | D32: ='Hito 4'!D10 -> To Do
A33: 4.6 | B33: El proceso base y su coste | C33: La convocatoria escrita como reglas, metida en la regresión, y medida con N de 10, 50 y 100. Ficheros: Backend/pruebas/modelos/. Terminada cuando el modelo corre de punta a punta y hay un número de segundos para cada N. | D33: ='Hito 4'!D11 -> To Do
A34: 5.1 | B34: Descriptor del participante | C34: instances, recursos infinitos, modo de llegada con su T, y la casilla de rechazo que termina el proceso. Ficheros: descriptors/participantWithoutLane.json. Terminada cuando los atributos se guardan en el .bpmn y se releen al abrirlo. | D34: ='Hito 5'!D6 -> To Do
A35: 5.2 | B35: Descriptores de los elementos nuevos | C35: Las tres tareas, el gateway, y la semilla en la colaboración. Ficheros: dos descriptores nuevos más collaboration.json. Terminada cuando los elementos conservan sus parámetros al guardar y volver a abrir. | D35: ='Hito 5'!D7 -> To Do
A36: 5.3 | B36: Paneles de propiedades | C36: Ficheros: provider/model/parts/, provider/properties/PropertiesProvider.js. Terminada cuando cada campo aparece solo donde tiene sentido: el número de instancias con el marcador puesto, el plazo y el cupo solo en el colector, el tope solo en la evaluadora. | D36: ='Hito 5'!D8 -> To Do
A37: 5.4 | B37: Iconos y renderizado | C37: Los tres tipos de tarea y el gateway nuevo. Ficheros: módulo nuevo en Modeler/lib/. Terminada cuando los cuatro se distinguen a simple vista en el lienzo y al imprimir en blanco y negro. | D37: ='Hito 5'!D9 -> To Do
A38: 5.5 | B38: Paleta y menú de reemplazo | C38: Ficheros: módulo nuevo. Terminada cuando se crean desde la paleta y una tarea normal se convierte en cualquiera de los tres tipos sin perder sus datos. | D38: ='Hito 5'!D10 -> To Do
A39: 5.6 | B39: Reglas de modelado de la asociación | C39: Ficheros: Modeler/lib/. Terminada cuando se puede trazar la asociación de gateway a tarea y de evaluadora a colector, y el editor la rechaza hacia cualquier otra cosa. | D39: ='Hito 5'!D11 -> To Do
A40: 5.7 | B40: Exportación de las reglas | C40: Todo lo anterior, incluidas las asociaciones, que hoy no se exportan. Ficheros: example/src/taskHandlers.js. Terminada cuando las reglas que saca el Modeler dan exactamente la misma simulación que las escritas a mano. | D40: ='Hito 5'!D12 -> To Do
A41: 5.8 | B41: Descarga de varios registros | C41: Ficheros: example/src/modeler.js, modeler.html, style.css. Terminada cuando la interfaz ofrece un XES por pool, cada uno con el nombre de su pool. | D41: ='Hito 5'!D13 -> To Do
...
